
<!DOCTYPE HTML>

<html lang="en">

<head>
  <meta charset="utf-8">
  <title>Django Exceptions - Django 1.9 - W3cubDocs</title>
  
  <meta name="description" content=" Django raises some of its own exceptions as well as standard Python exceptions. ">
  <meta name="keywords" content="django, exceptions, -, django~1.9">
  <meta name="HandheldFriendly" content="True">
  <meta name="MobileOptimized" content="320">
  <meta name="viewport" content="width=device-width, initial-scale=1">
  <meta name="mobile-web-app-capable" content="yes">
  
  <link rel="canonical" href="http://docs.w3cub.com/django~1.9/ref/exceptions/">
  <link href="/favicon.png" rel="icon">
  <link type="text/css" rel="stylesheet" href="/assets/application-50364fff564ce3b6327021805f3f00e2957b441cf27f576a7dd4ff63bbc47047.css">
  <script type="text/javascript" src="/assets/application-db64bfd54ceb42be11af7995804cf4902548419ceb79d509b0b7d62c22d98e6f.js"></script>
  <script src="/json/django~1.9.js"></script>
  
  <script type="text/javascript">
    var _gaq = _gaq || [];
    _gaq.push(['_setAccount', 'UA-71174418-1']);
    _gaq.push(['_trackPageview']);

    (function() {
      var ga = document.createElement('script'); ga.type = 'text/javascript'; ga.async = true;
      ga.src = ('https:' == document.location.protocol ? 'https://ssl' : 'http://www') + '.google-analytics.com/ga.js';
      var s = document.getElementsByTagName('script')[0]; s.parentNode.insertBefore(ga, s);
    })();
  </script>


</head>

<body>
	<div class="_app">
	<header class="_header">
  
  <form class="_search">
    <input type="search" class="_search-input" placeholder="Search&hellip;" autocomplete="off" autocapitalize="off" autocorrect="off" spellcheck="false" maxlength="20">
    <a class="_search-clear"></a>
    <div class="_search-tag"></div>
  </form>
  
  <a class="_home-link" href="/" ></a>
  <a class="_menu-link"></a>
  <h1 class="_logo">
    <a href="/" class="_nav-link" title="API Documentation Browser">W3cubDocs</a>
  </h1>
  
  <span class="_logo-sub-nav">/</span><span class="_logo-sub-nav"><a href="/django~1.9/" class="_nav-link" title="" style="margin-left:0;">Django 1.9</a></span>
  
  <nav class="_nav">
    <a href="/app/" class="_nav-link ">App</a>
    <a href="/about/" class="_nav-link ">About</a>
  </nav>
</header>
	<section class="_sidebar">
		<div class="_list">
			
		</div>
	</section>
	<section class="_container ">
		<div class="_content">
			<div class="_page _sphinx">
				
<h1 id="django-exceptions">Django Exceptions</h1> <p>Django raises some of its own exceptions as well as standard Python exceptions.</p>  <h2 id="django-core-exceptions">Django Core Exceptions</h2> <p id="module-django.core.exceptions">Django core exception classes are defined in <code>django.core.exceptions</code>.</p>  <h3 id="objectdoesnotexist"><code>ObjectDoesNotExist</code></h3> <dl class="exception"> <dt id="django.core.exceptions.ObjectDoesNotExist">
<code>exception ObjectDoesNotExist</code> <a class="reference internal" href="https://docs.djangoproject.com/en/1.9/_modules/django/core/exceptions/#ObjectDoesNotExist" target="_blank"><span class="viewcode-link">[source]</span></a>
</dt> <dd>
<p>The base class for <a class="reference internal" href="../models/instances/#django.db.models.Model.DoesNotExist" title="django.db.models.Model.DoesNotExist"><code>DoesNotExist</code></a> exceptions; a <code>try/except</code> for <code>ObjectDoesNotExist</code> will catch <a class="reference internal" href="../models/instances/#django.db.models.Model.DoesNotExist" title="django.db.models.Model.DoesNotExist"><code>DoesNotExist</code></a> exceptions for all models.</p> <p>See <a class="reference internal" href="../models/querysets/#django.db.models.query.QuerySet.get" title="django.db.models.query.QuerySet.get"><code>get()</code></a> for further information on <a class="reference internal" href="#django.core.exceptions.ObjectDoesNotExist" title="django.core.exceptions.ObjectDoesNotExist"><code>ObjectDoesNotExist</code></a> and <a class="reference internal" href="../models/instances/#django.db.models.Model.DoesNotExist" title="django.db.models.Model.DoesNotExist"><code>DoesNotExist</code></a>.</p> </dd>
</dl>   <h3 id="fielddoesnotexist"><code>FieldDoesNotExist</code></h3> <dl class="exception"> <dt id="django.core.exceptions.FieldDoesNotExist">
<code>exception FieldDoesNotExist</code> <a class="reference internal" href="https://docs.djangoproject.com/en/1.9/_modules/django/core/exceptions/#FieldDoesNotExist" target="_blank"><span class="viewcode-link">[source]</span></a>
</dt> <dd>
<p>The <code>FieldDoesNotExist</code> exception is raised by a model’s <code>_meta.get_field()</code> method when the requested field does not exist on the model or on the model’s parents.</p> <div class="versionchanged"> <p>This exception was previously defined only in <code>django.db.models.fields</code> and wasn’t part of the public API.</p> </div> </dd>
</dl>   <h3 id="multipleobjectsreturned"><code>MultipleObjectsReturned</code></h3> <dl class="exception"> <dt id="django.core.exceptions.MultipleObjectsReturned">
<code>exception MultipleObjectsReturned</code> <a class="reference internal" href="https://docs.djangoproject.com/en/1.9/_modules/django/core/exceptions/#MultipleObjectsReturned" target="_blank"><span class="viewcode-link">[source]</span></a>
</dt> <dd>
<p>The <a class="reference internal" href="#django.core.exceptions.MultipleObjectsReturned" title="django.core.exceptions.MultipleObjectsReturned"><code>MultipleObjectsReturned</code></a> exception is raised by a query if only one object is expected, but multiple objects are returned. A base version of this exception is provided in <a class="reference internal" href="#module-django.core.exceptions" title="django.core.exceptions: Django core exceptions"><code>django.core.exceptions</code></a>; each model class contains a subclassed version that can be used to identify the specific object type that has returned multiple objects.</p> <p>See <a class="reference internal" href="../models/querysets/#django.db.models.query.QuerySet.get" title="django.db.models.query.QuerySet.get"><code>get()</code></a> for further information.</p> </dd>
</dl>   <h3 id="suspiciousoperation"><code>SuspiciousOperation</code></h3> <dl class="exception"> <dt id="django.core.exceptions.SuspiciousOperation">
<code>exception SuspiciousOperation</code> <a class="reference internal" href="https://docs.djangoproject.com/en/1.9/_modules/django/core/exceptions/#SuspiciousOperation" target="_blank"><span class="viewcode-link">[source]</span></a>
</dt> <dd>
<p>The <a class="reference internal" href="#django.core.exceptions.SuspiciousOperation" title="django.core.exceptions.SuspiciousOperation"><code>SuspiciousOperation</code></a> exception is raised when a user has performed an operation that should be considered suspicious from a security perspective, such as tampering with a session cookie. Subclasses of <code>SuspiciousOperation</code> include:</p> <ul class="simple"> <li><code>DisallowedHost</code></li> <li><code>DisallowedModelAdminLookup</code></li> <li><code>DisallowedModelAdminToField</code></li> <li><code>DisallowedRedirect</code></li> <li><code>InvalidSessionKey</code></li> <li><code>SuspiciousFileOperation</code></li> <li><code>SuspiciousMultipartForm</code></li> <li><code>SuspiciousSession</code></li> </ul> <p>If a <code>SuspiciousOperation</code> exception reaches the WSGI handler level it is logged at the <code>Error</code> level and results in a <a class="reference internal" href="../request-response/#django.http.HttpResponseBadRequest" title="django.http.HttpResponseBadRequest"><code>HttpResponseBadRequest</code></a>. See the <a class="reference internal" href="../../topics/logging/"><span class="doc">logging documentation</span></a> for more information.</p> </dd>
</dl>   <h3 id="permissiondenied"><code>PermissionDenied</code></h3> <dl class="exception"> <dt id="django.core.exceptions.PermissionDenied">
<code>exception PermissionDenied</code> <a class="reference internal" href="https://docs.djangoproject.com/en/1.9/_modules/django/core/exceptions/#PermissionDenied" target="_blank"><span class="viewcode-link">[source]</span></a>
</dt> <dd>
<p>The <a class="reference internal" href="#django.core.exceptions.PermissionDenied" title="django.core.exceptions.PermissionDenied"><code>PermissionDenied</code></a> exception is raised when a user does not have permission to perform the action requested.</p> </dd>
</dl>   <h3 id="viewdoesnotexist"><code>ViewDoesNotExist</code></h3> <dl class="exception"> <dt id="django.core.exceptions.ViewDoesNotExist">
<code>exception ViewDoesNotExist</code> <a class="reference internal" href="https://docs.djangoproject.com/en/1.9/_modules/django/core/exceptions/#ViewDoesNotExist" target="_blank"><span class="viewcode-link">[source]</span></a>
</dt> <dd>
<p>The <a class="reference internal" href="#django.core.exceptions.ViewDoesNotExist" title="django.core.exceptions.ViewDoesNotExist"><code>ViewDoesNotExist</code></a> exception is raised by <a class="reference internal" href="../urlresolvers/#module-django.core.urlresolvers" title="django.core.urlresolvers"><code>django.core.urlresolvers</code></a> when a requested view does not exist.</p> </dd>
</dl>   <h3 id="middlewarenotused"><code>MiddlewareNotUsed</code></h3> <dl class="exception"> <dt id="django.core.exceptions.MiddlewareNotUsed">
<code>exception MiddlewareNotUsed</code> <a class="reference internal" href="https://docs.djangoproject.com/en/1.9/_modules/django/core/exceptions/#MiddlewareNotUsed" target="_blank"><span class="viewcode-link">[source]</span></a>
</dt> <dd>
<p>The <a class="reference internal" href="#django.core.exceptions.MiddlewareNotUsed" title="django.core.exceptions.MiddlewareNotUsed"><code>MiddlewareNotUsed</code></a> exception is raised when a middleware is not used in the server configuration.</p> </dd>
</dl>   <h3 id="improperlyconfigured"><code>ImproperlyConfigured</code></h3> <dl class="exception"> <dt id="django.core.exceptions.ImproperlyConfigured">
<code>exception ImproperlyConfigured</code> <a class="reference internal" href="https://docs.djangoproject.com/en/1.9/_modules/django/core/exceptions/#ImproperlyConfigured" target="_blank"><span class="viewcode-link">[source]</span></a>
</dt> <dd>
<p>The <a class="reference internal" href="#django.core.exceptions.ImproperlyConfigured" title="django.core.exceptions.ImproperlyConfigured"><code>ImproperlyConfigured</code></a> exception is raised when Django is somehow improperly configured – for example, if a value in <code>settings.py</code> is incorrect or unparseable.</p> </dd>
</dl>   <h3 id="fielderror"><code>FieldError</code></h3> <dl class="exception"> <dt id="django.core.exceptions.FieldError">
<code>exception FieldError</code> <a class="reference internal" href="https://docs.djangoproject.com/en/1.9/_modules/django/core/exceptions/#FieldError" target="_blank"><span class="viewcode-link">[source]</span></a>
</dt> <dd>
<p>The <a class="reference internal" href="#django.core.exceptions.FieldError" title="django.core.exceptions.FieldError"><code>FieldError</code></a> exception is raised when there is a problem with a model field. This can happen for several reasons:</p> <ul class="simple"> <li>A field in a model clashes with a field of the same name from an abstract base class</li> <li>An infinite loop is caused by ordering</li> <li>A keyword cannot be parsed from the filter parameters</li> <li>A field cannot be determined from a keyword in the query parameters</li> <li>A join is not permitted on the specified field</li> <li>A field name is invalid</li> <li>A query contains invalid order_by arguments</li> </ul> </dd>
</dl>   <h3 id="validationerror"><code>ValidationError</code></h3> <dl class="exception"> <dt id="django.core.exceptions.ValidationError">
<code>exception ValidationError</code> <a class="reference internal" href="https://docs.djangoproject.com/en/1.9/_modules/django/core/exceptions/#ValidationError" target="_blank"><span class="viewcode-link">[source]</span></a>
</dt> <dd>
<p>The <a class="reference internal" href="#django.core.exceptions.ValidationError" title="django.core.exceptions.ValidationError"><code>ValidationError</code></a> exception is raised when data fails form or model field validation. For more information about validation, see <a class="reference internal" href="../forms/validation/"><span class="doc">Form and Field Validation</span></a>, <a class="reference internal" href="../models/instances/#validating-objects"><span class="std std-ref">Model Field Validation</span></a> and the <a class="reference internal" href="../validators/"><span class="doc">Validator Reference</span></a>.</p> </dd>
</dl>  <h4 id="non-field-errors"><code>NON_FIELD_ERRORS</code></h4> <dl class="data"> <dt id="django.core.exceptions.NON_FIELD_ERRORS">
<code>NON_FIELD_ERRORS</code> </dt> 
</dl> <p><code>ValidationError</code>s that don’t belong to a particular field in a form or model are classified as <code>NON_FIELD_ERRORS</code>. This constant is used as a key in dictionaries that otherwise map fields to their respective list of errors.</p>     <h2 id="url-resolver-exceptions">URL Resolver exceptions</h2> <p>URL Resolver exceptions are defined in <code>django.core.urlresolvers</code>.</p>  <h3 id="resolver404"><code>Resolver404</code></h3> <dl class="exception"> <dt id="django.core.urlresolvers.Resolver404">
<code>exception Resolver404</code> <a class="reference internal" href="https://docs.djangoproject.com/en/1.9/_modules/django/core/urlresolvers/#Resolver404" target="_blank"><span class="viewcode-link">[source]</span></a>
</dt> <dd>
<p>The <a class="reference internal" href="#django.core.urlresolvers.Resolver404" title="django.core.urlresolvers.Resolver404"><code>Resolver404</code></a> exception is raised by <a class="reference internal" href="../urlresolvers/#django.core.urlresolvers.resolve" title="django.core.urlresolvers.resolve"><code>django.core.urlresolvers.resolve()</code></a> if the path passed to <code>resolve()</code> doesn’t map to a view. It’s a subclass of <a class="reference internal" href="../../topics/http/views/#django.http.Http404" title="django.http.Http404"><code>django.http.Http404</code></a>.</p> </dd>
</dl>   <h3 id="noreversematch"><code>NoReverseMatch</code></h3> <dl class="exception"> <dt id="django.core.urlresolvers.NoReverseMatch">
<code>exception NoReverseMatch</code> <a class="reference internal" href="https://docs.djangoproject.com/en/1.9/_modules/django/core/urlresolvers/#NoReverseMatch" target="_blank"><span class="viewcode-link">[source]</span></a>
</dt> <dd>
<p>The <a class="reference internal" href="#django.core.urlresolvers.NoReverseMatch" title="django.core.urlresolvers.NoReverseMatch"><code>NoReverseMatch</code></a> exception is raised by <a class="reference internal" href="../urlresolvers/#module-django.core.urlresolvers" title="django.core.urlresolvers"><code>django.core.urlresolvers</code></a> when a matching URL in your URLconf cannot be identified based on the parameters supplied.</p> </dd>
</dl>    <h2 id="database-exceptions">Database Exceptions</h2> <p>Database exceptions may be imported from <code>django.db</code>.</p> <p>Django wraps the standard database exceptions so that your Django code has a guaranteed common implementation of these classes.</p> <dl class="exception"> <dt id="django.db.Error">
<code>exception Error</code> <a class="reference internal" href="https://docs.djangoproject.com/en/1.9/_modules/django/db/utils/#Error" target="_blank"><span class="viewcode-link">[source]</span></a>
</dt> 
</dl> <dl class="exception"> <dt id="django.db.InterfaceError">
<code>exception InterfaceError</code> <a class="reference internal" href="https://docs.djangoproject.com/en/1.9/_modules/django/db/utils/#InterfaceError" target="_blank"><span class="viewcode-link">[source]</span></a>
</dt> 
</dl> <dl class="exception"> <dt id="django.db.DatabaseError">
<code>exception DatabaseError</code> <a class="reference internal" href="https://docs.djangoproject.com/en/1.9/_modules/django/db/utils/#DatabaseError" target="_blank"><span class="viewcode-link">[source]</span></a>
</dt> 
</dl> <dl class="exception"> <dt id="django.db.DataError">
<code>exception DataError</code> <a class="reference internal" href="https://docs.djangoproject.com/en/1.9/_modules/django/db/utils/#DataError" target="_blank"><span class="viewcode-link">[source]</span></a>
</dt> 
</dl> <dl class="exception"> <dt id="django.db.OperationalError">
<code>exception OperationalError</code> <a class="reference internal" href="https://docs.djangoproject.com/en/1.9/_modules/django/db/utils/#OperationalError" target="_blank"><span class="viewcode-link">[source]</span></a>
</dt> 
</dl> <dl class="exception"> <dt id="django.db.IntegrityError">
<code>exception IntegrityError</code> <a class="reference internal" href="https://docs.djangoproject.com/en/1.9/_modules/django/db/utils/#IntegrityError" target="_blank"><span class="viewcode-link">[source]</span></a>
</dt> 
</dl> <dl class="exception"> <dt id="django.db.InternalError">
<code>exception InternalError</code> <a class="reference internal" href="https://docs.djangoproject.com/en/1.9/_modules/django/db/utils/#InternalError" target="_blank"><span class="viewcode-link">[source]</span></a>
</dt> 
</dl> <dl class="exception"> <dt id="django.db.ProgrammingError">
<code>exception ProgrammingError</code> <a class="reference internal" href="https://docs.djangoproject.com/en/1.9/_modules/django/db/utils/#ProgrammingError" target="_blank"><span class="viewcode-link">[source]</span></a>
</dt> 
</dl> <dl class="exception"> <dt id="django.db.NotSupportedError">
<code>exception NotSupportedError</code> <a class="reference internal" href="https://docs.djangoproject.com/en/1.9/_modules/django/db/utils/#NotSupportedError" target="_blank"><span class="viewcode-link">[source]</span></a>
</dt> 
</dl> <p>The Django wrappers for database exceptions behave exactly the same as the underlying database exceptions. See <a class="pep reference external" href="https://www.python.org/dev/peps/pep-0249" id="index-0" target="_blank"><strong>PEP 249</strong></a>, the Python Database API Specification v2.0, for further information.</p> <p>As per <a class="pep reference external" href="https://www.python.org/dev/peps/pep-3134" id="index-1" target="_blank"><strong>PEP 3134</strong></a>, a <code>__cause__</code> attribute is set with the original (underlying) database exception, allowing access to any additional information provided. (Note that this attribute is available under both Python 2 and Python 3, although <a class="pep reference external" href="https://www.python.org/dev/peps/pep-3134" id="index-2" target="_blank"><strong>PEP 3134</strong></a> normally only applies to Python 3.)</p> <dl class="exception"> <dt id="django.db.models.ProtectedError">
<code>exception models.ProtectedError</code> </dt> 
</dl> <p>Raised to prevent deletion of referenced objects when using <a class="reference internal" href="../models/fields/#django.db.models.PROTECT" title="django.db.models.PROTECT"><code>django.db.models.PROTECT</code></a>. <a class="reference internal" href="#django.db.models.ProtectedError" title="django.db.models.ProtectedError"><code>models.ProtectedError</code></a> is a subclass of <a class="reference internal" href="#django.db.IntegrityError" title="django.db.IntegrityError"><code>IntegrityError</code></a>.</p>   <h2 id="http-exceptions">Http Exceptions</h2> <p>Http exceptions may be imported from <code>django.http</code>.</p>  <h3 id="unreadableposterror"><code>UnreadablePostError</code></h3> <dl class="exception"> <dt id="django.http.UnreadablePostError">
<code>exception UnreadablePostError</code> <a class="reference internal" href="https://docs.djangoproject.com/en/1.9/_modules/django/http/request/#UnreadablePostError" target="_blank"><span class="viewcode-link">[source]</span></a>
</dt> <dd>
<p><a class="reference internal" href="#django.http.UnreadablePostError" title="django.http.UnreadablePostError"><code>UnreadablePostError</code></a> is raised when a user cancels an upload.</p> </dd>
</dl>    <h2 id="transaction-exceptions">Transaction Exceptions</h2> <p>Transaction exceptions are defined in <code>django.db.transaction</code>.</p>  <h3 id="transactionmanagementerror"><code>TransactionManagementError</code></h3> <dl class="exception"> <dt id="django.db.transaction.TransactionManagementError">
<code>exception TransactionManagementError</code> <a class="reference internal" href="https://docs.djangoproject.com/en/1.9/_modules/django/db/transaction/#TransactionManagementError" target="_blank"><span class="viewcode-link">[source]</span></a>
</dt> <dd>
<p><a class="reference internal" href="#django.db.transaction.TransactionManagementError" title="django.db.transaction.TransactionManagementError"><code>TransactionManagementError</code></a> is raised for any and all problems related to database transactions.</p> </dd>
</dl>    <h2 id="testing-framework-exceptions">Testing Framework Exceptions</h2> <p>Exceptions provided by the <code>django.test</code> package.</p>  <h3 id="redirectcycleerror"><code>RedirectCycleError</code></h3> <dl class="exception"> <dt id="django.test.client.RedirectCycleError">
<code>exception client.RedirectCycleError</code> </dt> <dd>
 <p><a class="reference internal" href="#django.test.client.RedirectCycleError" title="django.test.client.RedirectCycleError"><code>RedirectCycleError</code></a> is raised when the test client detects a loop or an overly long chain of redirects.</p> </dd>
</dl>    <h2 id="python-exceptions">Python Exceptions</h2> <p>Django raises built-in Python exceptions when appropriate as well. See the Python documentation for further information on the <a class="reference external" href="https://docs.python.org/3/library/exceptions.html#bltin-exceptions" title="(in Python v3.6)" target="_blank"><span>Built-in Exceptions</span></a>.</p>
<div class="_attribution">
  <p class="_attribution-p">
    © Django Software Foundation and individual contributors<br>Licensed under the BSD License.<br>
    <a href="https://docs.djangoproject.com/en/1.9/ref/exceptions/" class="_attribution-link" target="_blank">https://docs.djangoproject.com/en/1.9/ref/exceptions/</a>
  </p>
</div>

			</div>
		</div>
	</section>

	</div>
</body>
</html>
