
<!DOCTYPE HTML>

<html lang="en">

<head>
  <meta charset="utf-8">
  <title>Try, Catch, and Rescue - Elixir 1.4 - W3cubDocs</title>
  
  <meta name="description" content="Elixir has three error mechanisms&#58; errors, throws, and exits. In this chapter we will explore each of them and include remarks about when each &hellip;">
  <meta name="keywords" content="try, catch, and, rescue, -, elixir, elixir~1.4">
  <meta name="HandheldFriendly" content="True">
  <meta name="MobileOptimized" content="320">
  <meta name="viewport" content="width=device-width, initial-scale=1">
  <meta name="mobile-web-app-capable" content="yes">
  
  <link rel="canonical" href="http://docs.w3cub.com/elixir~1.4/try-catch-and-rescue/">
  <link href="/favicon.png" rel="icon">
  <link type="text/css" rel="stylesheet" href="/assets/application-50364fff564ce3b6327021805f3f00e2957b441cf27f576a7dd4ff63bbc47047.css">
  <script type="text/javascript" src="/assets/application-db64bfd54ceb42be11af7995804cf4902548419ceb79d509b0b7d62c22d98e6f.js"></script>
  <script src="/json/elixir~1.4.js"></script>
  
  <script type="text/javascript">
    var _gaq = _gaq || [];
    _gaq.push(['_setAccount', 'UA-71174418-1']);
    _gaq.push(['_trackPageview']);

    (function() {
      var ga = document.createElement('script'); ga.type = 'text/javascript'; ga.async = true;
      ga.src = ('https:' == document.location.protocol ? 'https://ssl' : 'http://www') + '.google-analytics.com/ga.js';
      var s = document.getElementsByTagName('script')[0]; s.parentNode.insertBefore(ga, s);
    })();
  </script>


</head>

<body>
	<div class="_app">
	<header class="_header">
  
  <form class="_search">
    <input type="search" class="_search-input" placeholder="Search&hellip;" autocomplete="off" autocapitalize="off" autocorrect="off" spellcheck="false" maxlength="20">
    <a class="_search-clear"></a>
    <div class="_search-tag"></div>
  </form>
  
  <a class="_home-link" href="/" ></a>
  <a class="_menu-link"></a>
  <h1 class="_logo">
    <a href="/" class="_nav-link" title="API Documentation Browser">W3cubDocs</a>
  </h1>
  
  <span class="_logo-sub-nav">/</span><span class="_logo-sub-nav"><a href="/elixir~1.4/" class="_nav-link" title="" style="margin-left:0;">Elixir 1.4</a></span>
  
  <nav class="_nav">
    <a href="/app/" class="_nav-link ">App</a>
    <a href="/about/" class="_nav-link ">About</a>
  </nav>
</header>
	<section class="_sidebar">
		<div class="_list">
			
		</div>
	</section>
	<section class="_container ">
		<div class="_content">
			<div class="_page _elixir">
				
<h1 id="try-catch-and-rescue">try, catch, and rescue</h1>  <p>Elixir has three error mechanisms: errors, throws, and exits. In this chapter we will explore each of them and include remarks about when each should be used.</p> <h2 id="errors">Errors</h2> <p>Errors (or <em>exceptions</em>) are used when exceptional things happen in the code. A sample error can be retrieved by trying to add a number into an atom:</p> <pre>iex&gt; :foo + 1
** (ArithmeticError) bad argument in arithmetic expression
     :erlang.+(:foo, 1)
</pre> <p>A runtime error can be raised any time by using <code class="highlighter-rouge">raise/1</code>:</p> <pre>iex&gt; raise "oops"
** (RuntimeError) oops
</pre> <p>Other errors can be raised with <code class="highlighter-rouge">raise/2</code> passing the error name and a list of keyword arguments:</p> <pre>iex&gt; raise ArgumentError, message: "invalid argument foo"
** (ArgumentError) invalid argument foo
</pre> <p>You can also define your own errors by creating a module and using the <code class="highlighter-rouge">defexception</code> construct inside it; this way, you’ll create an error with the same name as the module it’s defined in. The most common case is to define a custom exception with a message field:</p> <pre>iex&gt; defmodule MyError do
iex&gt;   defexception message: "default message"
iex&gt; end
iex&gt; raise MyError
** (MyError) default message
iex&gt; raise MyError, message: "custom message"
** (MyError) custom message
</pre> <p>Errors can be <strong>rescued</strong> using the <code class="highlighter-rouge">try/rescue</code> construct:</p> <pre>iex&gt; try do
...&gt;   raise "oops"
...&gt; rescue
...&gt;   e in RuntimeError -&gt; e
...&gt; end
%RuntimeError{message: "oops"}
</pre> <p>The example above rescues the runtime error and returns the error itself which is then printed in the <code class="highlighter-rouge">iex</code> session.</p> <p>If you don’t have any use for the error, you don’t have to provide it:</p> <pre>iex&gt; try do
...&gt;   raise "oops"
...&gt; rescue
...&gt;   RuntimeError -&gt; "Error!"
...&gt; end
"Error!"
</pre> <p>In practice, however, Elixir developers rarely use the <code class="highlighter-rouge">try/rescue</code> construct. For example, many languages would force you to rescue an error when a file cannot be opened successfully. Elixir instead provides a <code class="highlighter-rouge">File.read/1</code> function which returns a tuple containing information about whether the file was opened successfully:</p> <pre>iex&gt; File.read "hello"
{:error, :enoent}
iex&gt; File.write "hello", "world"
:ok
iex&gt; File.read "hello"
{:ok, "world"}
</pre> <p>There is no <code class="highlighter-rouge">try/rescue</code> here. In case you want to handle multiple outcomes of opening a file, you can use pattern matching within the <code class="highlighter-rouge">case</code> construct:</p> <pre>iex&gt; case File.read "hello" do
...&gt;   {:ok, body}      -&gt; IO.puts "Success: #{body}"
...&gt;   {:error, reason} -&gt; IO.puts "Error: #{reason}"
...&gt; end
</pre> <p>At the end of the day, it’s up to your application to decide if an error while opening a file is exceptional or not. That’s why Elixir doesn’t impose exceptions on <code class="highlighter-rouge">File.read/1</code> and many other functions. Instead, it leaves it up to the developer to choose the best way to proceed.</p> <p>For the cases where you do expect a file to exist (and the lack of that file is truly an <em>error</em>) you may use <code class="highlighter-rouge">File.read!/1</code>:</p> <pre>iex&gt; File.read! "unknown"
** (File.Error) could not read file unknown: no such file or directory
    (elixir) lib/file.ex:305: File.read!/1
</pre> <p>Many functions in the standard library follow the pattern of having a counterpart that raises an exception instead of returning tuples to match against. The convention is to create a function (<code class="highlighter-rouge">foo</code>) which returns <code class="highlighter-rouge"><span class="p">{</span><span class="err">:ok,</span><span class="err">result</span><span class="p">}</span></code> or <code class="highlighter-rouge"><span class="p">{</span><span class="err">:error,</span><span class="err">reason</span><span class="p">}</span></code> tuples and another function (<code class="highlighter-rouge">foo!</code>, same name but with a trailing <code class="highlighter-rouge">!</code>) that takes the same arguments as <code class="highlighter-rouge">foo</code> but which raises an exception if there’s an error. <code class="highlighter-rouge">foo!</code> should return the result (not wrapped in a tuple) if everything goes fine. The <a href="https://hexdocs.pm/elixir/File.html" target="_blank"><code class="highlighter-rouge">File</code> module</a> is a good example of this convention.</p> <p>In Elixir, we avoid using <code class="highlighter-rouge">try/rescue</code> because <strong>we don’t use errors for control flow</strong>. We take errors literally: they are reserved for unexpected and/or exceptional situations. In case you actually need flow control constructs, <em>throws</em> should be used. That’s what we are going to see next.</p> <h2 id="throws">Throws</h2> <p>In Elixir, a value can be thrown and later be caught. <code class="highlighter-rouge">throw</code> and <code class="highlighter-rouge">catch</code> are reserved for situations where it is not possible to retrieve a value unless by using <code class="highlighter-rouge">throw</code> and <code class="highlighter-rouge">catch</code>.</p> <p>Those situations are quite uncommon in practice except when interfacing with libraries that do not provide a proper API. For example, let’s imagine the <code class="highlighter-rouge">Enum</code> module did not provide any API for finding a value and that we needed to find the first multiple of 13 in a list of numbers:</p> <pre>iex&gt; try do
...&gt;   Enum.each -50..50, fn(x) -&gt;
...&gt;     if rem(x, 13) == 0, do: throw(x)
...&gt;   end
...&gt;   "Got nothing"
...&gt; catch
...&gt;   x -&gt; "Got #{x}"
...&gt; end
"Got -39"
</pre> <p>Since <code class="highlighter-rouge">Enum</code> <em>does</em> provide a proper API, in practice <code class="highlighter-rouge">Enum.find/2</code> is the way to go:</p> <pre>iex&gt; Enum.find -50..50, &amp;(rem(&amp;1, 13) == 0)
-39
</pre> <h2 id="exits">Exits</h2> <p>All Elixir code runs inside processes that communicate with each other. When a process dies of “natural causes” (e.g., unhandled exceptions), it sends an <code class="highlighter-rouge">exit</code> signal. A process can also die by explicitly sending an exit signal:</p> <pre>iex&gt; spawn_link fn -&gt; exit(1) end
#PID&lt;0.56.0&gt;
** (EXIT from #PID&lt;0.56.0&gt;) 1
</pre> <p>In the example above, the linked process died by sending an <code class="highlighter-rouge">exit</code> signal with value of 1. The Elixir shell automatically handles those messages and prints them to the terminal.</p> <p><code class="highlighter-rouge">exit</code> can also be “caught” using <code class="highlighter-rouge">try/catch</code>:</p> <pre>iex&gt; try do
...&gt;   exit "I am exiting"
...&gt; catch
...&gt;   :exit, _ -&gt; "not really"
...&gt; end
"not really"
</pre> <p>Using <code class="highlighter-rouge">try/catch</code> is already uncommon and using it to catch exits is even more rare.</p> <p><code class="highlighter-rouge">exit</code> signals are an important part of the fault tolerant system provided by the Erlang <abbr title="Virtual Machine">VM</abbr>. Processes usually run under supervision trees which are themselves processes that listen to <code class="highlighter-rouge">exit</code> signals from the supervised processes. Once an exit signal is received, the supervision strategy kicks in and the supervised process is restarted.</p> <p>It is exactly this supervision system that makes constructs like <code class="highlighter-rouge">try/catch</code> and <code class="highlighter-rouge">try/rescue</code> so uncommon in Elixir. Instead of rescuing an error, we’d rather “fail fast” since the supervision tree will guarantee our application will go back to a known initial state after the error.</p> <h2 id="after">After</h2> <p>Sometimes it’s necessary to ensure that a resource is cleaned up after some action that could potentially raise an error. The <code class="highlighter-rouge">try/after</code> construct allows you to do that. For example, we can open a file and use an <code class="highlighter-rouge">after</code> clause to close it–even if something goes wrong:</p> <pre>iex&gt; {:ok, file} = File.open "sample", [:utf8, :write]
iex&gt; try do
...&gt;   IO.write file, "olá"
...&gt;   raise "oops, something went wrong"
...&gt; after
...&gt;   File.close(file)
...&gt; end
** (RuntimeError) oops, something went wrong
</pre> <p>The <code class="highlighter-rouge">after</code> clause will be executed regardless of whether or not the tried block succeeds. Note, however, that if a linked process exits, this process will exit and the <code class="highlighter-rouge">after</code> clause will not get run. Thus <code class="highlighter-rouge">after</code> provides only a soft guarantee. Luckily, files in Elixir are also linked to the current processes and therefore they will always get closed if the current process crashes, independent of the <code class="highlighter-rouge">after</code> clause. You will find the same to be true for other resources like ETS tables, sockets, ports and more.</p> <p>Sometimes you may want to wrap the entire body of a function in a <code class="highlighter-rouge">try</code> construct, often to guarantee some code will be executed afterwards. In such cases, Elixir allows you to omit the <code class="highlighter-rouge">try</code> line:</p> <pre>iex&gt; defmodule RunAfter do
...&gt;   def without_even_trying do
...&gt;     raise "oops"
...&gt;   after
...&gt;     IO.puts "cleaning up!"
...&gt;   end
...&gt; end
iex&gt; RunAfter.without_even_trying
cleaning up!
** (RuntimeError) oops
</pre> <p>Elixir will automatically wrap the function body in a <code class="highlighter-rouge">try</code> whenever one of <code class="highlighter-rouge">after</code>, <code class="highlighter-rouge">rescue</code> or <code class="highlighter-rouge">catch</code> is specified.</p> <h2 id="else">Else</h2> <p>Providing an <code class="highlighter-rouge">else</code> block allows for pattern matching on the result of the expression executed.</p> <pre>x = 2
try do
  1 / x
rescue
  ArithmeticError -&gt;
    :infinity
else
  y when y &lt; 1 and y &gt; -1 -&gt;
    :small
  _ -&gt;
    :large
end
</pre> <p>The result is passed to <code class="highlighter-rouge">else</code> where it can be pattern matched. Please note that the <code class="highlighter-rouge">else</code> block is also executed if an exception has been caught, the result of the <code class="highlighter-rouge">catch/rescue</code> block will then be passed in.</p> <p>Exceptions in the <code class="highlighter-rouge">else</code> block are not caught. If no pattern inside the <code class="highlighter-rouge">else</code> block matches an exception will be raised, this exception is not caught by the current <code class="highlighter-rouge">try/catch/rescue/after</code> block.</p> <h2 id="variables-scope">Variables scope</h2> <p>It is important to bear in mind that variables defined inside <code class="highlighter-rouge">try/catch/rescue/after</code> blocks do not leak to the outer context. This is because the <code class="highlighter-rouge">try</code> block may fail and as such the variables may never be bound in the first place. In other words, this code is invalid:</p> <pre>iex&gt; try do
...&gt;   raise "fail"
...&gt;   what_happened = :did_not_raise
...&gt; rescue
...&gt;   _ -&gt; what_happened = :rescued
...&gt; end
iex&gt; what_happened
** (RuntimeError) undefined function: what_happened/0
</pre> <p>Instead, you can store the value of the <code class="highlighter-rouge">try</code> expression:</p> <pre>iex&gt; what_happened =
...&gt;   try do
...&gt;     raise "fail"
...&gt;     :did_not_raise
...&gt;   rescue
...&gt;     _ -&gt; :rescued
...&gt;   end
iex&gt; what_happened
:rescued
</pre> <p>This finishes our introduction to <code class="highlighter-rouge">try</code>, <code class="highlighter-rouge">catch</code>, and <code class="highlighter-rouge">rescue</code>. You will find they are used less frequently in Elixir than in other languages, although they may be handy in some situations where a library or some particular code is not playing “by the rules”.</p>
<div class="_attribution">
  <p class="_attribution-p">
    © 2012–2017 Plataformatec<br>Licensed under the Apache License, Version 2.0.<br>
    <a href="http://elixir-lang.org/getting-started/try-catch-and-rescue.html" class="_attribution-link" target="_blank">http://elixir-lang.org/getting-started/try-catch-and-rescue.html</a>
  </p>
</div>

			</div>
		</div>
	</section>

	</div>
</body>
</html>
